Workbook

Sheet CartasAtributos
A1: Planilha de Atributos
A3: Camada | B3: Carta | C3: Categoria 1 | D3: Atributo 1 | E3: Categoria 2 | F3: Atributo 2 | H3: Categorias | I3: Atributos | J3: Usos | L3: Categorias | M3: Atributos | N3: Usos
A5: 1 | B5: Branco | C5: Origem | D5: Mitológico | E5: Vibe | F5: Elegante | H5: Origem | I5: Natural | J5: =COUNTIF(D5:D33,"Natural")+COUNTIF(F5:F33,"Natural") -> 3 | L5: Paleta | M5: Neutro | N5: =COUNTIF(D5:D33,"Neutro")+COUNTIF(F5:F33,"Neutro") -> 2 | R5: =COUNTIFS(CartasAtributos!D$5:D$98,"Natural",CartasAtributos!F$5:F$98,"Fofo")+COUNTIFS(CartasAtributos!D$5:D$98,"Fofo",CartasAtributos!F$5:F$98,"Natural") -> 0
A6: 1 | B6: Bege | C6: Origem | D6: Natural | E6: Paleta | F6: Pastel | I6: Mitológico | J6: =COUNTIF(D5:D33,"Mitológico")+COUNTIF(F5:F33,"Mitológico") -> 2 | M6: Pastel | N6: =COUNTIF(D5:D33,"Pastel")+COUNTIF(F5:F33,"Pastel") -> 3
A7: 1 | B7: Creme | C7: Origem | D7: Natural | E7: Tema | F7: Infantil | I7: Cósmico | J7: =COUNTIF(D5:D33,"Cósmico")+COUNTIF(F5:F33,"Cósmico") -> 2 | M7: Vibrante | N7: =COUNTIF(D5:D33,"Vibrante")+COUNTIF(F5:F33,"Vibrante") -> 2
A8: 1 | B8: Ocre | C8: Tema | D8: Comédia | E8: Celebração | F8: Festa Junina | I8: Mágico | J8: =COUNTIF(D5:D33,"Mágico")+COUNTIF(F5:F33,"Mágico") -> 2 | M8: Quente | N8: =COUNTIF(D5:D33,"Quente")+COUNTIF(F5:F33,"Quente") -> 2
A9: 1 | B9: Amarelo Pastel | C9: Vibe | D9: Fofo | E9: Celebração | F9: Páscoa | I9: Geek | J9: =COUNTIF(D5:D33,"Geek")+COUNTIF(F5:F33,"Geek") -> 3 | M9: Frio | N9: =COUNTIF(D5:D33,"Frio")+COUNTIF(F5:F33,"Frio") -> 3
A10: 1 | B10: Amarelo | C10: Paleta | D10: Quente | E10: Celebração | F10: Carnaval
A11: 1 | B11: Terracota | C11: Tema | D11: Comédia | E11: Paleta | F11: Neutro | H11: Vibe | I11: Fofo | J11: =COUNTIF(D5:D33,"Fofo")+COUNTIF(F5:F33,"Fofo") -> 2 | L11: Celebração | M11: Carnaval | N11: =COUNTIF(D5:D33,"Carnaval")+COUNTIF(F5:F33,"Carnaval") -> 2
A12: 1 | B12: Vermelho | C12: Vibe | D12: Romântico | E12: Celebração | F12: Natal | I12: Romântico | J12: =COUNTIF(D5:D33,"Romântico")+COUNTIF(F5:F33,"Romântico") -> 2 | M12: Páscoa | N12: =COUNTIF(D5:D33,"Páscoa")+COUNTIF(F5:F33,"Páscoa") -> 2
A13: 1 | B13: Vermelho Escuro | C13: Origem | D13: Mitológico | E13: Tema | F13: Terror | I13: Elegante | J13: =COUNTIF(D5:D33,"Elegante")+COUNTIF(F5:F33,"Elegante") -> 3 | M13: Festa Junina | N13: =COUNTIF(D5:D33,"Festa Junina")+COUNTIF(F5:F33,"Festa Junina") -> 3
A14: 1 | B14: Rosa Pastel | C14: Vibe | D14: Fofo | E14: Tema | F14: Infantil | I14: Selvagem | J14: =COUNTIF(D5:D33,"Selvagem")+COUNTIF(F5:F33,"Selvagem") -> 2 | M14: Halloween | N14: =COUNTIF(D5:D33,"Halloween")+COUNTIF(F5:F33,"Halloween") -> 2
A15: 1 | B15: Rosa | C15: Vibe | D15: Romântico | E15: Paleta | F15: Vibrante | I15: Sombrio | J15: =COUNTIF(D5:D33,"Sombrio")+COUNTIF(F5:F33,"Sombrio") -> 2 | M15: Natal | N15: =COUNTIF(D5:D33,"Natal")+COUNTIF(F5:F33,"Natal") -> 2
A16: 1 | B16: Rosa Escuro | C16: Origem | D16: Mágico | E16: Vibe | F16: Sombrio
A17: 1 | B17: Magenta | C17: Origem | D17: Geek | E17: Tema | F17: Sci-fi | H17: Tema | I17: Infantil | J17: =COUNTIF(D5:D33,"Infantil")+COUNTIF(F5:F33,"Infantil") -> 3 | M17: Total: | N17: {=SUM(J5:J9+J11:J15+J17:J21+N5:N9+N11:N15)} -> 58
A18: 1 | B18: Roxo Pastel | C18: Paleta | D18: Pastel | E18: Celebração | F18: Páscoa | I18: Comédia | J18: =COUNTIF(D5:D33,"Comédia")+COUNTIF(F5:F33,"Comédia") -> 2
A19: 1 | B19: Roxo | C19: Tema | D19: Sci-fi | E19: Paleta | F19: Quente | I19: Drama | J19: =COUNTIF(D5:D33,"Drama")+COUNTIF(F5:F33,"Drama") -> 2
A20: 1 | B20: Roxo Escuro | C20: Origem | D20: Mágico | E20: Tema | F20: Terror | I20: Sci-fi | J20: =COUNTIF(D5:D33,"Sci-fi")+COUNTIF(F5:F33,"Sci-fi") -> 3
A21: 1 | B21: Azul Pastel | C21: Tema | D21: Infantil | E21: Celebração | F21: Festa Junina | I21: Terror | J21: =COUNTIF(D5:D33,"Terror")+COUNTIF(F5:F33,"Terror") -> 2
A22: 1 | B22: Azul | C22: Origem | D22: Geek | E22: Paleta | F22: Frio
A23: 1 | B23: Azul Escuro | C23: Origem | D23: Cósmico | E23: Paleta | F23: Frio
A24: 1 | B24: Verde Água | C24: Tema | D24: Sci-fi | E24: Paleta | F24: Vibrante
A25: 1 | B25: Teal | C25: Origem | D25: Geek | E25: Celebração | F25: Carnaval
A26: 1 | B26: Verde Pastel | C26: Paleta | D26: Pastel | E26: Celebração | F26: Festa Junina
A27: 1 | B27: Verde | C27: Paleta | D27: Frio | E27: Celebração | F27: Natal
A28: 1 | B28: Verde Escuro | C28: Vibe | D28: Selvagem | E28: Celebração | F28: Halloween
A29: 1 | B29: Marrom | C29: Origem | D29: Natural | E29: Vibe | F29: Selvagem
A30: 1 | B30: Cinza Claro | C30: Tema | D30: Drama | E30: Paleta | F30: Neutro
A31: 1 | B31: Cinza Médio | C31: Vibe | D31: Elegante | E31: Tema | F31: Drama
A32: 1 | B32: Cinza Escuro | C32: Vibe | D32: Sombrio | E32: Celebração | F32: Halloween
A33: 1 | B33: Preto | C33: Origem | D33: Cósmico | E33: Vibe | F33: Elegante
A35: Camada | B35: Carta | C35: Categoria 1 | D35: Atributo 1 | E35: Categoria 2 | F35: Atributo 2 | H35: Categorias | I35: Atributos | J35: Usos | L35: Categorias | M35: Atributos | N35: Usos
A37: 2 | B37: Tuxedo | C37: Vibe | D37: Elegante | E37: Tema | F37: Comédia | H37: Origem | I37: Natural | J37: =COUNTIF(D37:D66,"Natural")+COUNTIF(F37:F66,"Natural") -> 2 | L37: Paleta | M37: Neutro | N37: =COUNTIF(D37:D66,"Neutro")+COUNTIF(F37:F66,"Neutro") -> 2
A38: 2 | B38: Color Point | C38: Paleta | D38: Neutro | E38: Celebração | F38: Páscoa | I38: Mitológico | J38: =COUNTIF(D37:D66,"Mitológico")+COUNTIF(F37:F66,"Mitológico") -> 3 | M38: Pastel | N38: =COUNTIF(D37:D66,"Pastel")+COUNTIF(F37:F66,"Pastel") -> 2
A39: 2 | B39: Mink | C39: Vibe | D39: Elegante | E39: Paleta | F39: Frio | I39: Cósmico | J39: =COUNTIF(D37:D66,"Cósmico")+COUNTIF(F37:F66,"Cósmico") -> 3 | M39: Vibrante | N39: =COUNTIF(D37:D66,"Vibrante")+COUNTIF(F37:F66,"Vibrante") -> 3
A40: 2 | B40: Calico | C40: Vibe | D40: Fofo | E40: Paleta | F40: Quente | I40: Mágico | J40: =COUNTIF(D37:D66,"Mágico")+COUNTIF(F37:F66,"Mágico") -> 2 | M40: Quente | N40: =COUNTIF(D37:D66,"Quente")+COUNTIF(F37:F66,"Quente") -> 2
A41: 2 | B41: Torbie | C41: Vibe | D41: Selvagem | E41: Celebração | F41: Natal | I41: Geek | J41: =COUNTIF(D37:D66,"Geek")+COUNTIF(F37:F66,"Geek") -> 2 | M41: Frio | N41: =COUNTIF(D37:D66,"Frio")+COUNTIF(F37:F66,"Frio") -> 2
A42: 2 | B42: Tortoiseshell | C42: Origem | D42: Natural | E42: Celebração | F42: Festa Junina
A43: 2 | B43: Harlequin | C43: Vibe | D43: Romântico | E43: Celebração | F43: Festa Junina | H43: Vibe | I43: Fofo | J43: =COUNTIF(D37:D66,"Fofo")+COUNTIF(F37:F66,"Fofo") -> 3 | L43: Celebração | M43: Carnaval | N43: =COUNTIF(D37:D66,"Carnaval")+COUNTIF(F37:F66,"Carnaval") -> 3
A44: 2 | B44: Tabby | C44: Origem | D44: Natural | E44: Paleta | F44: Neutro | I44: Romântico | J44: =COUNTIF(D37:D66,"Romântico")+COUNTIF(F37:F66,"Romântico") -> 2 | M44: Páscoa | N44: =COUNTIF(D37:D66,"Páscoa")+COUNTIF(F37:F66,"Páscoa") -> 2
...

Sheet CombinaçõesCategorias
A1: Combinação de Categoria
A3: Categoria 1 | B3: + | C3: Categoria2 | D3: Usos
A5: Origem | C5: Vibe | D5: =COUNTIFS(CartasAtributos!C$5:C$98,"Origem",CartasAtributos!E$5:E$98,"Vibe")+COUNTIFS(CartasAtributos!C$5:C$98,"Vibe",CartasAtributos!E$5:E$98,"Origem") -> 9 | F5: Top 5
A6: Origem | C6: Tema | D6: =COUNTIFS(CartasAtributos!C$5:C$98,"Origem",CartasAtributos!E$5:E$98,"Tema")+COUNTIFS(CartasAtributos!C$5:C$98,"Tema",CartasAtributos!E$5:E$98,"Origem") -> 9 | F6: Top 5
A7: Origem | C7: Paleta | D7: =COUNTIFS(CartasAtributos!C$5:C$98,"Origem",CartasAtributos!E$5:E$98,"Paleta")+COUNTIFS(CartasAtributos!C$5:C$98,"Paleta",CartasAtributos!E$5:E$98,"Origem") -> 11 | F7: Top 2
A8: Origem | C8: Celebração | D8: =COUNTIFS(CartasAtributos!C$5:C$98,"Origem",CartasAtributos!E$5:E$98,"Celebração")+COUNTIFS(CartasAtributos!C$5:C$98,"Celebração",CartasAtributos!E$5:E$98,"Origem") -> 6
A9: Vibe | C9: Tema | D9: =COUNTIFS(CartasAtributos!C$5:C$98,"Vibe",CartasAtributos!E$5:E$98,"Tema")+COUNTIFS(CartasAtributos!C$5:C$98,"Tema",CartasAtributos!E$5:E$98,"Vibe") -> 7
A10: Vibe | C10: Paleta | D10: =COUNTIFS(CartasAtributos!C$5:C$98,"Vibe",CartasAtributos!E$5:E$98,"Paleta")+COUNTIFS(CartasAtributos!C$5:C$98,"Paleta",CartasAtributos!E$5:E$98,"Vibe") -> 6
A11: Vibe | C11: Celebração | D11: =COUNTIFS(CartasAtributos!C$5:C$98,"Vibe",CartasAtributos!E$5:E$98,"Celebração")+COUNTIFS(CartasAtributos!C$5:C$98,"Celebração",CartasAtributos!E$5:E$98,"Vibe") -> 14 | F11: Top 1
A12: Tema | C12: Paleta | D12: =COUNTIFS(CartasAtributos!C$5:C$98,"Tema",CartasAtributos!E$5:E$98,"Paleta")+COUNTIFS(CartasAtributos!C$5:C$98,"Paleta",CartasAtributos!E$5:E$98,"Tema") -> 10 | F12: Top 3
A13: Tema | C13: Celebração | D13: =COUNTIFS(CartasAtributos!C$5:C$98,"Tema",CartasAtributos!E$5:E$98,"Celebração")+COUNTIFS(CartasAtributos!C$5:C$98,"Celebração",CartasAtributos!E$5:E$98,"Tema") -> 7
A14: Paleta | C14: Celebração | D14: =COUNTIFS(CartasAtributos!C$5:C$98,"Paleta",CartasAtributos!E$5:E$98,"Celebração")+COUNTIFS(CartasAtributos!C$5:C$98,"Celebração",CartasAtributos!E$5:E$98,"Paleta") -> 8

Sheet CombinaçõesAtributos
B1: Combinação de Atributo
A3: Categoria 1 | B3: Atributo 1 | C3: + | D3: Categoria2 | E3: Atributo 2 | F3: Usos
A4: Origem | B4: Natural | D4: Vibe | E4: Fofo | F4: =COUNTIFS(CartasAtributos!D$5:D$98,B4,CartasAtributos!F$5:F$98,E4)+COUNTIFS(CartasAtributos!D$5:D$98,E4,CartasAtributos!F$5:F$98,B4) -> 0
A5: Origem | B5: Natural | D5: Vibe | E5: Romântico | F5: =COUNTIFS(CartasAtributos!D$5:D$98,B5,CartasAtributos!F$5:F$98,E5)+COUNTIFS(CartasAtributos!D$5:D$98,E5,CartasAtributos!F$5:F$98,B5) -> 0
A6: Origem | B6: Natural | D6: Vibe | E6: Elegante | F6: =COUNTIFS(CartasAtributos!D$5:D$98,B6,CartasAtributos!F$5:F$98,E6)+COUNTIFS(CartasAtributos!D$5:D$98,E6,CartasAtributos!F$5:F$98,B6) -> 0
A7: Origem | B7: Natural | D7: Vibe | E7: Selvagem | F7: =COUNTIFS(CartasAtributos!D$5:D$98,B7,CartasAtributos!F$5:F$98,E7)+COUNTIFS(CartasAtributos!D$5:D$98,E7,CartasAtributos!F$5:F$98,B7) -> 1
A8: Origem | B8: Natural | D8: Vibe | E8: Sombrio | F8: =COUNTIFS(CartasAtributos!D$5:D$98,B8,CartasAtributos!F$5:F$98,E8)+COUNTIFS(CartasAtributos!D$5:D$98,E8,CartasAtributos!F$5:F$98,B8) -> 0
A9: Origem | B9: Mitológico | D9: Vibe | E9: Fofo | F9: =COUNTIFS(CartasAtributos!D$5:D$98,B9,CartasAtributos!F$5:F$98,E9)+COUNTIFS(CartasAtributos!D$5:D$98,E9,CartasAtributos!F$5:F$98,B9) -> 0
A10: Origem | B10: Mitológico | D10: Vibe | E10: Romântico | F10: =COUNTIFS(CartasAtributos!D$5:D$98,B10,CartasAtributos!F$5:F$98,E10)+COUNTIFS(CartasAtributos!D$5:D$98,E10,CartasAtributos!F$5:F$98,B10) -> 0
A11: Origem | B11: Mitológico | D11: Vibe | E11: Elegante | F11: =COUNTIFS(CartasAtributos!D$5:D$98,B11,CartasAtributos!F$5:F$98,E11)+COUNTIFS(CartasAtributos!D$5:D$98,E11,CartasAtributos!F$5:F$98,B11) -> 1
A12: Origem | B12: Mitológico | D12: Vibe | E12: Selvagem | F12: =COUNTIFS(CartasAtributos!D$5:D$98,B12,CartasAtributos!F$5:F$98,E12)+COUNTIFS(CartasAtributos!D$5:D$98,E12,CartasAtributos!F$5:F$98,B12) -> 0
A13: Origem | B13: Mitológico | D13: Vibe | E13: Sombrio | F13: =COUNTIFS(CartasAtributos!D$5:D$98,B13,CartasAtributos!F$5:F$98,E13)+COUNTIFS(CartasAtributos!D$5:D$98,E13,CartasAtributos!F$5:F$98,B13) -> 0
A14: Origem | B14: Cósmico | D14: Vibe | E14: Fofo | F14: =COUNTIFS(CartasAtributos!D$5:D$98,B14,CartasAtributos!F$5:F$98,E14)+COUNTIFS(CartasAtributos!D$5:D$98,E14,CartasAtributos!F$5:F$98,B14) -> 0
A15: Origem | B15: Cósmico | D15: Vibe | E15: Romântico | F15: =COUNTIFS(CartasAtributos!D$5:D$98,B15,CartasAtributos!F$5:F$98,E15)+COUNTIFS(CartasAtributos!D$5:D$98,E15,CartasAtributos!F$5:F$98,B15) -> 0
... A253: Paleta | B253: Frio | D253: Celebração | E253: Natal | F253: =COUNTIFS(CartasAtributos!D$5:D$98,B253,CartasAtributos!F$5:F$98,E253)+COUNTIFS(CartasAtributos!D$5:D$98,E253,CartasAtributos!F$5:F$98,B253) -> 1
E255: Total: | F255: =SUM(F4:F253) -> 87
